#VRML_SIM R2020b utf8
WorldInfo {
  coordinateSystem "NUE"
}
Viewpoint {
  orientation -0.009321367686661244 0.9769241009070483 0.21338325419630588 3.4922467909794337
  position -0.3053390499508504 0.2086626528852387 -0.7651420724878254
}
TexturedBackground {
}
TexturedBackgroundLight {
}
RectangleArena {
  floorSize 2 2
  floorAppearance Appearance {
    material Material {
      ambientIntensity 0
      diffuseColor 1 1 1
      emissiveColor 1 1 1
      shininess 0
      specularColor 1 1 1
    }
    texture ImageTexture {
      url [
        "textures/circulo_large.jpg"
      ]
      repeatS FALSE
      repeatT FALSE
    }
    textureTransform TextureTransform {
      scale 0.25 0.25
    }
  }
}
DEF Quebra-molas Solid {
  translation 0.29 0 0
  rotation 1 0 0 -1.5707953071795862
  children [
    DEF quebra-molas Shape {
      appearance PBRAppearance {
      }
      geometry Cylinder {
        height 0.25
        radius 0.01
      }
    }
  ]
  boundingObject USE quebra-molas
}
Robot {
  translation -0.0015876280796123146 0.029857921400008765 0.001119682603899176
  rotation 0 -1 0 0
  children [
    DEF RodaL HingeJoint {
      jointParameters HingeJointParameters {
        position -0.7518717270497757
        axis 0 1 0
        anchor -0.1 0 0
      }
      endPoint Solid {
        translation -0.1 0 0
        rotation 0 -1 0 0.7518717270497758
        children [
          DEF JuntaRoda HingeJoint {
            jointParameters HingeJointParameters {
              position -890.8081624664128
              axis 0 0 1
              anchor -0.013 -0.02 0
            }
            endPoint Solid {
              translation -0.013 -0.02 0
              rotation -0.8977138195607555 0.31153692704303243 -0.3115359389512294 1.678490196112933
              children [
                DEF CalotaRodaL Transform {
                  children [
                    Shape {
                      appearance PBRAppearance {
                        baseColorMap ImageTexture {
                          url [
                            "textures/calota_preta.jpg"
                          ]
                        }
                        metalness 0
                      }
                      geometry Cylinder {
                        height 0.005
                        radius 0.009
                      }
                    }
                  ]
                }
                DEF rodaLroda Shape {
                  appearance PBRAppearance {
                    baseColor 0 0 0
                    metalness 0
                  }
                  geometry Cylinder {
                    height 0.0045
                    radius 0.01
                  }
                }
              ]
              boundingObject USE rodaLroda
              physics Physics {
              }
            }
          }
          DEF rodaLEixoHorizontal Transform {
            translation -0.006 -0.016 0
            rotation 0 0 1 2.0944
            children [
              Shape {
                appearance PBRAppearance {
                  baseColor 0.580392 0.580392 0.580392
                  metalness 0
                }
                geometry Capsule {
                  height 0.015
                  radius 0.005
                  subdivision 24
                }
              }
            ]
          }
          DEF rodaLEixoVertical Transform {
            translation 0 -0.005 0
            children [
              Shape {
                appearance PBRAppearance {
                  baseColor 0.580392 0.580392 0.580392
                  metalness 0
                }
                geometry Capsule {
                  height 0.015
                  radius 0.005
                  subdivision 24
                }
              }
            ]
          }
        ]
        name "solid(2)"
        boundingObject Group {
          children [
            USE rodaLEixoHorizontal
            USE rodaLEixoVertical
          ]
        }
        physics Physics {
        }
      }
    }
    DEF RodaE HingeJoint {
      jointParameters HingeJointParameters {
        position 48.42459120864195
        axis 0 0 -1
        anchor 0.05 0 -0.07
      }
      device [
        RotationalMotor {
          name "motorE"
        }
      ]
      endPoint Solid {
        translation 0.049998483861980705 1.1958136402934634e-06 -0.06999983082182952
        rotation -0.47941716518804445 -0.6203006917667302 -0.6207948401177117 4.036307682648759
        children [
          DEF Calota Transform {
            children [
              Shape {
                appearance PBRAppearance {
                  baseColor 1 1 0
                  baseColorMap ImageTexture {
                    url [
                      "textures/calota_preta.jpg"
                    ]
                  }
                  metalness 0
                }
                geometry Cylinder {
                  height 0.031
                  radius 0.029
                }
              }
            ]
          }
          DEF rodaE Shape {
            appearance PBRAppearance {
              baseColorMap ImageTexture {
                url [
                  "textures/caster_wheel_base_color.jpg"
                ]
              }
              metalness 0
            }
            geometry Cylinder {
              height 0.03
              radius 0.03
            }
          }
        ]
        boundingObject USE rodaE
        physics Physics {
        }
      }
    }
    DEF RodaD HingeJoint {
      jointParameters HingeJointParameters {
        position 20.297029909659376
        axis 0 0 -1
        anchor 0.05 0 0.07
      }
      device [
        RotationalMotor {
          name "motorD"
        }
      ]
      endPoint Solid {
        translation 0.04999784802051031 -1.7556412832587492e-07 0.07000060851369364
        rotation -0.631134041121335 0.5482662120053549 0.5487020893992957 4.268306288595461
        children [
          DEF Calota Transform {
            children [
              Shape {
                appearance PBRAppearance {
                  baseColor 1 1 0
                  baseColorMap ImageTexture {
                    url [
                      "textures/calota_preta.jpg"
                    ]
                  }
                  metalness 0
                }
                geometry Cylinder {
                  height 0.031
                  radius 0.029
                }
              }
            ]
          }
          DEF rodaD Shape {
            appearance PBRAppearance {
              baseColorMap ImageTexture {
                url [
                  "textures/caster_wheel.jpg"
                ]
              }
              metalness 0
            }
            geometry Cylinder {
              height 0.03
              radius 0.03
            }
          }
        ]
        name "solid(1)"
        boundingObject USE rodaD
        physics Physics {
        }
      }
    }
    DEF Corpo Transform {
      children [
        Shape {
          appearance PBRAppearance {
            baseColor 0.666667 0.666667 0
            baseColorMap ImageTexture {
              url [
                "textures/desktop_wood.jpg"
              ]
            }
            metalness 0
          }
          geometry Box {
            size 0.22 0.01 0.16
          }
        }
      ]
    }
  ]
  name "Robo_Ifes"
  boundingObject Group {
    children [
      USE Corpo
    ]
  }
  physics Physics {
  }
  controller "ex01_c_cont"
}
