#VRML_SIM R2021a utf8
WorldInfo {
  coordinateSystem "NUE"
}
Viewpoint {
  orientation -0.24628879585878083 -0.9568172142160317 -0.154410646052351 1.160106882735893
  position -1.1068747019541396 0.43534180627163316 0.784922003588751
}
TexturedBackground {
}
TexturedBackgroundLight {
}
RectangleArena {
  floorSize 2 2
  floorAppearance Appearance {
    material Material {
      ambientIntensity 0
      diffuseColor 1 1 1
      emissiveColor 1 1 1
      shininess 0
      specularColor 1 1 1
    }
    texture ImageTexture {
      url [
        "textures/circulo_large.jpg"
      ]
      repeatS FALSE
      repeatT FALSE
    }
    textureTransform TextureTransform {
      scale 0.25 0.25
    }
  }
}
DEF Quebra-molas Solid {
  translation 0.5442661861953809 0.009938361952124341 0.11976112798184195
  rotation 0.6166146092623425 0.296264450109047 0.7293927606206637 -1.667163335314445
  children [
    DEF quebra-molas Shape {
      appearance PBRAppearance {
      }
      geometry Cylinder {
        height 0.25
        radius 0.01
      }
    }
  ]
  boundingObject USE quebra-molas
  physics Physics {
  }
  linearVelocity -0.009890039199970535 9.552503129691248e-14 -0.024307720496158088
  angularVelocity -2.430772049615819 3.1364642187672744e-17 0.9890039199970521
}
Robot {
  translation -0.1142135461191291 0.029088094529339012 -0.3096419186827449
  rotation 0.006432094299528634 0.9028448041596577 0.4299184664152392 0.035007520789897745
  children [
    DistanceSensor {
      translation 0.1 -0.005 0.07
      rotation 0 0 -1 1.5707996938995747
      children [
        DEF SensorInfravermelho Group {
          children [
            DEF Base Transform {
              children [
                Shape {
                  appearance PBRAppearance {
                    baseColor 0.1 0.1 0.1
                    roughness 1
                    metalness 0
                    IBLStrength 0
                  }
                  geometry Box {
                    size 0.005 0.012 0.0058
                  }
                }
              ]
            }
            DEF Receptor Transform {
              translation 0.002 -0.0025 0
              rotation 0 0 1 1.5708
              children [
                Shape {
                  appearance PBRAppearance {
                    baseColor 0.2 0.1 0.2
                  }
                  geometry Capsule {
                    height 0.005
                    radius 0.0015
                  }
                }
              ]
            }
            DEF Emissor Transform {
              translation 0.002 0.0025 0
              rotation 0 0 1 1.5708
              children [
                Shape {
                  appearance PBRAppearance {
                    baseColor 0.4 0.4 1
                  }
                  geometry Capsule {
                    height 0.005
                    radius 0.0015
                  }
                }
              ]
            }
          ]
        }
      ]
      name "l1"
      boundingObject USE SensorInfravermelho
      physics Physics {
      }
      type "infra-red"
    }
    DistanceSensor {
      translation 0.1 -0.005 0.035
      rotation 0 0 -1 1.5707996938995747
      children [
        DEF tcrt Shape {
          appearance PBRAppearance {
          }
          geometry Box {
            size 0.01 0.01 0.005
          }
        }
      ]
      name "l2"
      boundingObject USE tcrt
      physics Physics {
      }
      type "infra-red"
    }
    DistanceSensor {
      translation 0.1 -0.005 0
      rotation 0 0 -1 1.5707996938995747
      children [
        DEF tcrt Shape {
          appearance PBRAppearance {
          }
          geometry Box {
            size 0.01 0.01 0.005
          }
        }
      ]
      name "l3"
      boundingObject USE tcrt
      physics Physics {
      }
      type "infra-red"
    }
    DistanceSensor {
      translation 0.1 -0.005 -0.035
      rotation 0 0 -1 1.5707996938995747
      children [
        DEF tcrt Shape {
          appearance PBRAppearance {
          }
          geometry Box {
            size 0.01 0.01 0.005
          }
        }
      ]
      name "l4"
      boundingObject USE tcrt
      physics Physics {
      }
      type "infra-red"
    }
    DistanceSensor {
      translation 0.1 -0.005 -0.07
      rotation 0 0 -1 1.5707996938995747
      children [
        DEF tcrt Shape {
          appearance PBRAppearance {
          }
          geometry Box {
            size 0.01 0.01 0.005
          }
        }
      ]
      name "l5"
      boundingObject USE tcrt
      physics Physics {
      }
      type "infra-red"
    }
    DistanceSensor {
      translation 0.1085 0.015 0
      children [
        DEF SensorUltrassonico Group {
          children [
            DEF Base Transform {
              children [
                Shape {
                  appearance PBRAppearance {
                    baseColor 0.1 0.2 1
                  }
                  geometry Box {
                    size 0.0015 0.02 0.045
                  }
                }
              ]
            }
            DEF Cilindro_1 Transform {
              translation 0.005 0 0.013
              rotation 0 0 1 -1.5707996938995747
              children [
                Shape {
                  appearance PBRAppearance {
                    baseColor 0.454902 0.454902 0.678431
                    metalness 0.5
                    normalMapFactor 0.5
                    emissiveColor 0.1 0.1 0.1
                  }
                  geometry Cylinder {
                    height 0.012
                    radius 0.008
                  }
                }
              ]
              translationStep 0
            }
            DEF Cilindro_2 Transform {
              translation 0.005 0 -0.013
              rotation 0 0 1 -1.5707996938995747
              children [
                Shape {
                  appearance PBRAppearance {
                    baseColor 0.454902 0.454902 0.678431
                    metalness 0.5
                    normalMapFactor 0.5
                    emissiveColor 0.1 0.1 0.1
                  }
                  geometry Cylinder {
                    height 0.012
                    radius 0.008
                  }
                }
              ]
              translationStep 0
            }
          ]
        }
      ]
      name "d1"
      contactMaterial ""
      boundingObject USE SensorUltrassonico
      physics Physics {
      }
      recognitionColors [
        1 1 1
      ]
      type "sonar"
      numberOfRays 5
      aperture 1
      resolution 0.001
    }
    DEF RodaL HingeJoint {
      jointParameters HingeJointParameters {
        position 3.1599141199546734
        axis 0 1 0
        anchor -0.1 0 0
      }
      endPoint Solid {
        translation -0.1000000183397012 1.6210927591894782e-06 3.3586555045245485e-10
        rotation 0 0.9999999999999999 0 3.1599141199546734
        children [
          DEF JuntaRoda HingeJoint {
            jointParameters HingeJointParameters {
              position -160.19745097236222
              axis 0 0 1
              anchor -0.02 -0.018 0
            }
            endPoint Solid {
              translation -0.02 -0.018 0
              rotation -0.7580282752570167 -0.4611896660872113 0.46119109467252184 1.8443538026691153
              children [
                DEF CalotaRodaL Transform {
                  children [
                    Shape {
                      appearance PBRAppearance {
                        baseColorMap ImageTexture {
                          url [
                            "textures/calota_preta.jpg"
                          ]
                        }
                        metalness 0
                      }
                      geometry Cylinder {
                        height 0.005
                        radius 0.009
                      }
                    }
                  ]
                }
                DEF rodaLroda Shape {
                  appearance PBRAppearance {
                    baseColor 0 0 0
                    metalness 0
                  }
                  geometry Cylinder {
                    height 0.0045
                    radius 0.01
                  }
                }
              ]
              boundingObject USE rodaLroda
              physics Physics {
              }
              linearVelocity -8.394588659380617e-09 -2.1428878077263695e-07 -1.2558674380988523e-08
              angularVelocity -1.4401909993502446e-06 -5.417517031909298e-07 8.488241599702622e-07
            }
          }
          DEF rodaLEixoHorizontal Transform {
            translation -0.01 -0.018 0
            rotation 0 0 1 1.5708
            children [
              Shape {
                appearance PBRAppearance {
                  baseColor 0.580392 0.580392 0.580392
                  metalness 0
                }
                geometry Capsule {
                  height 0.02
                  radius 0.005
                  subdivision 24
                }
              }
            ]
          }
          DEF rodaLEixoVertical Transform {
            translation 0 -0.007 0
            children [
              Shape {
                appearance PBRAppearance {
                  baseColor 0.580392 0.580392 0.580392
                  metalness 0
                }
                geometry Capsule {
                  height 0.02
                  radius 0.005
                  subdivision 24
                }
              }
            ]
          }
        ]
        name "roda_boba"
        boundingObject Group {
          children [
            USE rodaLEixoHorizontal
            USE rodaLEixoVertical
          ]
        }
        physics Physics {
        }
        linearVelocity -1.2831258303459551e-08 -2.263078663373908e-07 -2.797878821391384e-08
        angularVelocity -1.4442380910497465e-06 -5.417752375309032e-07 7.678717234769321e-07
      }
    }
    DEF RodaE HingeJoint {
      jointParameters HingeJointParameters {
        position 60.526330670752074
        axis 0 0 -1
        anchor 0.05 0 -0.07
      }
      device [
        RotationalMotor {
          name "motorE"
        }
      ]
      endPoint Solid {
        translation 0.04999625675679334 9.138825047285175e-07 -0.0699998308138625
        rotation 0.30319091557334854 0.6735546940432294 0.6740914944175801 2.5523852179385074
        children [
          DEF Calota Transform {
            children [
              Shape {
                appearance PBRAppearance {
                  baseColor 1 1 0
                  baseColorMap ImageTexture {
                    url [
                      "textures/calota_preta.jpg"
                    ]
                  }
                  metalness 0
                }
                geometry Cylinder {
                  height 0.031
                  radius 0.029
                }
              }
            ]
          }
          DEF rodaE Shape {
            appearance PBRAppearance {
              baseColorMap ImageTexture {
                url [
                  "textures/caster_wheel_base_color.jpg"
                ]
              }
              metalness 0
            }
            geometry Cylinder {
              height 0.03
              radius 0.03
            }
          }
        ]
        name "roda_esquerda"
        boundingObject USE rodaE
        physics Physics {
        }
        linearVelocity -2.1574019367793225e-08 -2.2766698608486569e-07 -4.548204969462365e-08
        angularVelocity -1.451671390139888e-06 -4.655381788563483e-08 7.679219005181165e-07
      }
    }
    DEF RodaD HingeJoint {
      jointParameters HingeJointParameters {
        position 60.52602915974902
        axis 0 0 -1
        anchor 0.05 0 0.07
      }
      device [
        RotationalMotor {
          name "motorD"
        }
      ]
      endPoint Solid {
        translation 0.0499997529624676 1.9375380998417973e-06 0.07000060852157688
        rotation 0.2912395451077384 0.6761850235866873 0.6767224994357058 2.5743648975485884
        children [
          DEF Calota Transform {
            children [
              Shape {
                appearance PBRAppearance {
                  baseColor 1 1 0
                  baseColorMap ImageTexture {
                    url [
                      "textures/calota_preta.jpg"
                    ]
                  }
                  metalness 0
                }
                geometry Cylinder {
                  height 0.031
                  radius 0.029
                }
              }
            ]
          }
          DEF rodaD Shape {
            appearance PBRAppearance {
              baseColorMap ImageTexture {
                url [
                  "textures/caster_wheel.jpg"
                ]
              }
              metalness 0
            }
            geometry Cylinder {
              height 0.03
              radius 0.03
            }
          }
        ]
        name "roda_direita"
        boundingObject USE rodaD
        physics Physics {
        }
        linearVelocity -2.460210693642879e-08 -2.4184946132691226e-08 -4.346241971768414e-08
        angularVelocity -1.4516721642660154e-06 -4.657990970782959e-08 7.681467563963343e-07
      }
    }
    DEF Estrutura Transform {
      children [
        Shape {
          appearance PBRAppearance {
            baseColor 0.666667 0.666667 0
            baseColorMap ImageTexture {
              url [
                "textures/desktop_wood.jpg"
              ]
            }
            metalness 0
          }
          geometry Box {
            size 0.22 0.01 0.16
          }
        }
      ]
    }
  ]
  name "Robo_Ifes"
  boundingObject USE Estrutura
  physics Physics {
  }
  controller "ex01_c_cont"
}
