#VRML_SIM R2021a utf8
WorldInfo {
  coordinateSystem "NUE"
}
Viewpoint {
  orientation 0.9999750005208197 0.004999916668645527 0.004999916668645865 4.712363980593017
  position -0.9487279667534879 4.032979548724111 0.7457964504128951
}
TexturedBackground {
}
TexturedBackgroundLight {
}
RectangleArena {
  rotation 1 0 0 4.6928012867022945e-06
  floorSize 2.5 2
  floorAppearance Appearance {
    material Material {
      diffuseColor 1 1 1
    }
  }
}
DEF Obstaculo Solid {
  translation 0.22203 0.0518926 -0.692188
  children [
    DEF Obstaculo Shape {
      appearance Asphalt {
      }
      geometry Box {
        size 0.1 0.1 0.1
      }
    }
  ]
  boundingObject USE Obstaculo
}
Robot {
  translation -0.9550534058461743 0.02917341305257072 0.7966527386605204
  rotation -0.006942363775224633 -0.999652391786023 0.02543421281847844 0.5050020957677169
  children [
    DistanceSensor {
      translation 0.08 -0.005 0.026
      rotation 0 0 -1 1.5707996938995747
      children [
        DEF SensorInfravermelho Group {
          children [
            DEF Base Transform {
              children [
                Shape {
                  appearance PBRAppearance {
                    baseColor 0.1 0.1 0.1
                    roughness 1
                    metalness 0
                    IBLStrength 0
                  }
                  geometry Box {
                    size 0.005 0.012 0.0058
                  }
                }
              ]
            }
            DEF Receptor Transform {
              translation 0.002 -0.0025 0
              rotation 0 0 1 1.5708
              children [
                Shape {
                  appearance PBRAppearance {
                    baseColor 0.2 0.1 0.2
                  }
                  geometry Capsule {
                    height 0.005
                    radius 0.0015
                  }
                }
              ]
            }
            DEF Emissor Transform {
              translation 0.002 0.0025 0
              rotation 0 0 1 1.5708
              children [
                Shape {
                  appearance PBRAppearance {
                    baseColor 0.4 0.4 1
                  }
                  geometry Capsule {
                    height 0.005
                    radius 0.0015
                  }
                }
              ]
            }
          ]
        }
      ]
      name "l1"
      boundingObject USE SensorInfravermelho
      physics Physics {
      }
      type "infra-red"
    }
    DistanceSensor {
      translation 0.08 -0.005 0.013
      rotation 0 0 -1 1.5707996938995747
      children [
        DEF SensorInfravermelho Group {
          children [
            DEF Base Transform {
              children [
                Shape {
                  appearance PBRAppearance {
                    baseColor 0.1 0.1 0.1
                    roughness 1
                    metalness 0
                    IBLStrength 0
                  }
                  geometry Box {
                    size 0.005 0.012 0.0058
                  }
                }
              ]
            }
            DEF Receptor Transform {
              translation 0.002 -0.0025 0
              rotation 0 0 1 1.5708
              children [
                Shape {
                  appearance PBRAppearance {
                    baseColor 0.2 0.1 0.2
                  }
                  geometry Capsule {
                    height 0.005
                    radius 0.0015
                  }
                }
              ]
            }
            DEF Emissor Transform {
              translation 0.002 0.0025 0
              rotation 0 0 1 1.5708
              children [
                Shape {
                  appearance PBRAppearance {
                    baseColor 0.4 0.4 1
                  }
                  geometry Capsule {
                    height 0.005
                    radius 0.0015
                  }
                }
              ]
            }
          ]
        }
      ]
      name "l2"
      boundingObject USE SensorInfravermelho
      physics Physics {
      }
      type "infra-red"
    }
    DistanceSensor {
      translation 0.1 -0.005 0
      rotation 0 0 -1 1.5707996938995747
      children [
        DEF SensorInfravermelho Group {
          children [
            DEF Base Transform {
              children [
                Shape {
                  appearance PBRAppearance {
                    baseColor 0.1 0.1 0.1
                    roughness 1
                    metalness 0
                    IBLStrength 0
                  }
                  geometry Box {
                    size 0.005 0.012 0.0058
                  }
                }
              ]
            }
            DEF Receptor Transform {
              translation 0.002 -0.0025 0
              rotation 0 0 1 1.5708
              children [
                Shape {
                  appearance PBRAppearance {
                    baseColor 0.2 0.1 0.2
                  }
                  geometry Capsule {
                    height 0.005
                    radius 0.0015
                  }
                }
              ]
            }
            DEF Emissor Transform {
              translation 0.002 0.0025 0
              rotation 0 0 1 1.5708
              children [
                Shape {
                  appearance PBRAppearance {
                    baseColor 0.4 0.4 1
                  }
                  geometry Capsule {
                    height 0.005
                    radius 0.0015
                  }
                }
              ]
            }
          ]
        }
      ]
      name "l3"
      boundingObject USE SensorInfravermelho
      physics Physics {
      }
      type "infra-red"
    }
    DistanceSensor {
      translation 0.08 -0.005 -0.013
      rotation 0 0 -1 1.5707996938995747
      children [
        DEF SensorInfravermelho Group {
          children [
            DEF Base Transform {
              children [
                Shape {
                  appearance PBRAppearance {
                    baseColor 0.1 0.1 0.1
                    roughness 1
                    metalness 0
                    IBLStrength 0
                  }
                  geometry Box {
                    size 0.005 0.012 0.0058
                  }
                }
              ]
            }
            DEF Receptor Transform {
              translation 0.002 -0.0025 0
              rotation 0 0 1 1.5708
              children [
                Shape {
                  appearance PBRAppearance {
                    baseColor 0.2 0.1 0.2
                  }
                  geometry Capsule {
                    height 0.005
                    radius 0.0015
                  }
                }
              ]
            }
            DEF Emissor Transform {
              translation 0.002 0.0025 0
              rotation 0 0 1 1.5708
              children [
                Shape {
                  appearance PBRAppearance {
                    baseColor 0.4 0.4 1
                  }
                  geometry Capsule {
                    height 0.005
                    radius 0.0015
                  }
                }
              ]
            }
          ]
        }
      ]
      name "l4"
      boundingObject USE SensorInfravermelho
      physics Physics {
      }
      type "infra-red"
    }
    DistanceSensor {
      translation 0.08 -0.005 -0.026
      rotation 0 0 -1 1.5707996938995747
      children [
        DEF SensorInfravermelho Group {
          children [
            DEF Base Transform {
              children [
                Shape {
                  appearance PBRAppearance {
                    baseColor 0.1 0.1 0.1
                    roughness 1
                    metalness 0
                    IBLStrength 0
                  }
                  geometry Box {
                    size 0.005 0.012 0.0058
                  }
                }
              ]
            }
            DEF Receptor Transform {
              translation 0.002 -0.0025 0
              rotation 0 0 1 1.5708
              children [
                Shape {
                  appearance PBRAppearance {
                    baseColor 0.2 0.1 0.2
                  }
                  geometry Capsule {
                    height 0.005
                    radius 0.0015
                  }
                }
              ]
            }
            DEF Emissor Transform {
              translation 0.002 0.0025 0
              rotation 0 0 1 1.5708
              children [
                Shape {
                  appearance PBRAppearance {
                    baseColor 0.4 0.4 1
                  }
                  geometry Capsule {
                    height 0.005
                    radius 0.0015
                  }
                }
              ]
            }
          ]
        }
      ]
      name "l5"
      boundingObject USE SensorInfravermelho
      physics Physics {
      }
      type "infra-red"
    }
    DistanceSensor {
      translation 0.1085 0.015 0
      children [
        DEF SensorUltrassonico Group {
          children [
            DEF Base Transform {
              children [
                Shape {
                  appearance PBRAppearance {
                    baseColor 0.1 0.2 1
                  }
                  geometry Box {
                    size 0.0015 0.02 0.045
                  }
                }
              ]
            }
            DEF Cilindro_1 Transform {
              translation 0.005 0 0.013
              rotation 0 0 1 -1.5707996938995747
              children [
                Shape {
                  appearance PBRAppearance {
                    baseColor 0.454902 0.454902 0.678431
                    metalness 0.5
                    normalMapFactor 0.5
                    emissiveColor 0.1 0.1 0.1
                  }
                  geometry Cylinder {
                    height 0.012
                    radius 0.008
                  }
                }
              ]
              translationStep 0
            }
            DEF Cilindro_2 Transform {
              translation 0.005 0 -0.013
              rotation 0 0 1 -1.5707996938995747
              children [
                Shape {
                  appearance PBRAppearance {
                    baseColor 0.454902 0.454902 0.678431
                    metalness 0.5
                    normalMapFactor 0.5
                    emissiveColor 0.1 0.1 0.1
                  }
                  geometry Cylinder {
                    height 0.012
                    radius 0.008
                  }
                }
              ]
              translationStep 0
            }
          ]
        }
      ]
      name "d1"
      contactMaterial ""
      boundingObject USE SensorUltrassonico
      physics Physics {
      }
      recognitionColors [
        1 1 1
      ]
      type "sonar"
      aperture 1
      resolution 0.001
    }
    DEF RodaL HingeJoint {
      jointParameters HingeJointParameters {
        position 20.600631489359497
        axis 0 1 0
        anchor -0.1 0 0
      }
      endPoint Solid {
        translation -0.10000000328875927 1.6210927591894653e-06 -1.8045539833303675e-08
        rotation 0 -1 0 4.532109739358849
        children [
          DEF JuntaRoda HingeJoint {
            jointParameters HingeJointParameters {
              position -41374.08933897793
              axis 0 0 1
              anchor -0.02 -0.018 0
            }
            endPoint Solid {
              translation -0.02 -0.018 0
              rotation 0.6482107315053321 -0.5384344616071842 0.538434005348013 4.29182716965191
              children [
                DEF CalotaRodaL Transform {
                  children [
                    Shape {
                      appearance PBRAppearance {
                        baseColorMap ImageTexture {
                          url [
                            "textures/calota_preta.jpg"
                          ]
                        }
                        metalness 0
                      }
                      geometry Cylinder {
                        height 0.005
                        radius 0.009
                      }
                    }
                  ]
                }
                DEF rodaLroda Shape {
                  appearance PBRAppearance {
                    baseColor 0 0 0
                    metalness 0
                  }
                  geometry Cylinder {
                    height 0.0045
                    radius 0.01
                  }
                }
              ]
              boundingObject USE rodaLroda
              physics Physics {
              }
              linearVelocity 0.037107345698649125 2.2017511872535762e-07 -0.09837667730387517
              angularVelocity -9.971383539401575 -0.8849279272867944 -3.6547376492776147
            }
          }
          DEF rodaLEixoHorizontal Transform {
            translation -0.01 -0.018 0
            rotation 0 0 1 1.5708
            children [
              Shape {
                appearance PBRAppearance {
                  baseColor 0.580392 0.580392 0.580392
                  metalness 0
                }
                geometry Capsule {
                  height 0.02
                  radius 0.005
                  subdivision 24
                }
              }
            ]
          }
          DEF rodaLEixoVertical Transform {
            translation 0 -0.007 0
            children [
              Shape {
                appearance PBRAppearance {
                  baseColor 0.580392 0.580392 0.580392
                  metalness 0
                }
                geometry Capsule {
                  height 0.02
                  radius 0.005
                  subdivision 24
                }
              }
            ]
          }
        ]
        name "roda_boba"
        boundingObject Group {
          children [
            USE rodaLEixoHorizontal
            USE rodaLEixoVertical
          ]
        }
        physics Physics {
        }
        linearVelocity 0.04690128615539412 -1.330612447970216e-06 -0.09474848492694325
        angularVelocity -0.00010201190059010885 -0.694958968111571 -2.1640348390214873e-05
      }
    }
    DEF RodaE HingeJoint {
      jointParameters HingeJointParameters {
        position 6706.11459029295
        axis 0 0 -1
        anchor 0.05 0 -0.07
      }
      device [
        RotationalMotor {
          name "motorE"
        }
      ]
      endPoint Solid {
        translation 0.05000080904303386 -3.767293498797666e-06 -0.0699998308138625
        rotation -0.42620813566117527 0.6394113431110969 0.6399216822370443 3.9479537081250786
        children [
          DEF Calota Transform {
            children [
              Shape {
                appearance PBRAppearance {
                  baseColor 1 1 0
                  baseColorMap ImageTexture {
                    url [
                      "textures/calota_preta.jpg"
                    ]
                  }
                  metalness 0
                }
                geometry Cylinder {
                  height 0.031
                  radius 0.029
                }
              }
            ]
          }
          DEF rodaE Shape {
            appearance PBRAppearance {
              baseColorMap ImageTexture {
                url [
                  "textures/caster_wheel_base_color.jpg"
                ]
              }
              metalness 0
            }
            geometry Cylinder {
              height 0.03
              radius 0.03
            }
          }
        ]
        name "roda_esquerda"
        boundingObject USE rodaE
        physics Physics {
        }
        linearVelocity 0.04356474256066466 2.1787499003109066e-06 0.023513821366541756
        angularVelocity 0.945694873514256 -0.7149398209545417 -1.762371400235983
      }
    }
    DEF RodaD HingeJoint {
      jointParameters HingeJointParameters {
        position -3268.0648943124565
        axis 0 0 -1
        anchor 0.05 0 0.07
      }
      device [
        RotationalMotor {
          name "motorD"
        }
      ]
      endPoint Solid {
        translation 0.05000191416328998 3.886648042327582e-07 0.07000060852157688
        rotation 0.8483403314258645 0.3742298768930157 0.37452727713331213 1.7337490997555538
        children [
          DEF Calota Transform {
            children [
              Shape {
                appearance PBRAppearance {
                  baseColor 1 1 0
                  baseColorMap ImageTexture {
                    url [
                      "textures/calota_preta.jpg"
                    ]
                  }
                  metalness 0
                }
                geometry Cylinder {
                  height 0.031
                  radius 0.029
                }
              }
            ]
          }
          DEF rodaD Shape {
            appearance PBRAppearance {
              baseColorMap ImageTexture {
                url [
                  "textures/caster_wheel.jpg"
                ]
              }
              metalness 0
            }
            geometry Cylinder {
              height 0.03
              radius 0.03
            }
          }
        ]
        name "roda_direita"
        boundingObject USE rodaD
        physics Physics {
        }
        linearVelocity -0.043837710010796914 -2.107140351763918e-06 -0.02348607071375572
        angularVelocity -0.9455989136686452 -0.7141944973131286 1.7624969474332302
      }
    }
    DEF Estrutura Transform {
      children [
        Shape {
          appearance PBRAppearance {
            baseColor 0.666667 0.666667 0
            baseColorMap ImageTexture {
              url [
                "textures/desktop_wood.jpg"
              ]
            }
            metalness 0
          }
          geometry Box {
            size 0.22 0.01 0.16
          }
        }
      ]
    }
  ]
  name "Robo_Ifes"
  boundingObject USE Estrutura
  physics Physics {
  }
  controller "controlador-principal"
  linearVelocity 0.015824229324407517 1.3624935796328011e-06 -0.029675633070847626
  angularVelocity 4.810380499018687e-05 -0.7079820685292824 6.141567608920772e-05
}
DEF Caminho Solid {
  scale 0.01 0.01 0.01
  children [
    Solid {
      name "obj_0"
    }
    Solid {
      children [
        Shape {
          appearance PBRAppearance {
            baseColor 0 0 0
            roughness 1
            metalness 0
            name "color_16777215"
          }
          geometry IndexedFaceSet {
            coord Coordinate {
              point [
                79 -0.005 -69.995, 79 0.005 -69.995, 79 -0.005 31.005, 79 0.005 31.005, 10 0.005 31.005, 77 0.005 29.005, 10 0.005 29.005, -18 0.005 -69.995, -18 -0.005 -69.995, -18 -0.005 -69.399, -18 0.005 -69.399, 77 0.005 -67.995, 10 -0.005 -9.995, 10 0.005 -9.995, 10 -0.005 29.005, -24.77 -0.005 -63.304, -24.77 0.005 -63.304, -23 -0.005 -9.995, -23 0.005 -9.995, -25 0.005 -9.995, -25 -0.005 -9.995, 77 -0.005 29.005, 10 -0.005 31.005, -23 0.005 0.005, -23 -0.005 0.005, -25 -0.005 0.005, -25 0.005 0.005, -24.4918 -0.005 -62.995, -25 -0.005 -62.995, -25 0.005 -62.995, -24.4918 0.005 -62.995, 77 -0.005 -67.995, -43 0.005 -39.995, -43 -0.005 -39.995, -25 0.005 -39.995, -31.0025 0.005 29.005, -25 0.005 23.601, -25 -0.005 23.601, -30 0.005 31.005, -30 -0.005 31.005, -30 -0.005 30.7949, -30 0.005 30.7949, -25 0.005 -41.995, -43 -0.005 -41.995, -43 0.005 -41.995, -30.431 0.005 31.183, -30.2333 0.005 31.005, -30.5913 0.005 31.005, -31.0025 -0.005 29.005, -23 0.005 -62.2051, -25 -0.005 -41.995, -25 -0.005 -39.995, -70 0.005 -9.995, -80 -0.005 -9.995, -80 0.005 -9.995, -70 -0.005 29.005, -70 0.005 29.005, 0 -0.005 -9.995, 0 0.005 -9.995, -70 0.005 70.005, -70 -0.005 70.005, -70 -0.005 31.005, -70 0.005 31.005, -70 -0.005 -9.995, -23 -0.005 -62.2051, -30.2333 -0.005 31.005, -30.431 -0.005 31.183, -30.5913 -0.005 31.005, -72 0.005 29.005, -72 -0.005 29.005, -72 -0.005 31.005, -72 0.005 31.005, 0 0.005 70.005, -80 -0.005 70.005, -80 0.005 70.005, -71.998 -0.005 31.005, -71.998 0.005 31.005, -23.5708 -0.005 25.005, -71.998 0.005 29.005, 0 -0.005 70.005, -16.5708 0.005 -67.995, -71.998 0.005 -7.998, -78.003 0.005 -7.998, -71.998 -0.005 29.005, -78.003 0.005 68.008, -71.998 0.005 68.008, -78.003 -0.005 -7.998, 10 0.005 70.005, -16.5708 -0.005 -67.995, -71.998 -0.005 -7.998, -78.003 -0.005 68.008, -71.998 -0.005 68.008, 10 -0.005 70.005, -23.5708 0.005 25.005, -23 0.005 25.005, -23 -0.005 25.005
              ]
            }
            coordIndex [
              0, 1, 2, -1, 3, 2, 1, -1, 4, 5, 6, -1, 7, 8, 9, -1, 7, 9, 10, -1, 3, 11, 5, -1, 4, 3, 5, -1, 12, 13, 6, -1, 12, 6, 14, -1, 1, 11, 3, -1, 10, 9, 15, -1, 10, 15, 16, -1, 17, 18, 19, -1, 17, 19, 20, -1, 14, 21, 22, -1, 23, 24, 25, -1, 23, 25, 26, -1, 27, 28, 29, -1, 27, 29, 30, -1, 2, 22, 21, -1, 31, 2, 21, -1, 2, 31, 0, -1, 32, 33, 34, -1, 35, 36, 37, -1, 3, 4, 22, -1, 3, 22, 2, -1, 38, 39, 40, -1, 38, 40, 41, -1, 42, 43, 44, -1, 45, 46, 47, -1, 35, 37, 48, -1, 18, 49, 34, -1, 19, 18, 34, -1, 42, 34, 49, -1, 49, 30, 42, -1, 29, 42, 30, -1, 7, 1, 0, -1, 32, 34, 44, -1, 42, 44, 34, -1, 43, 50, 51, -1, 43, 51, 33, -1, 52, 53, 54, -1, 55, 56, 48, -1, 35, 48, 56, -1, 13, 12, 57, -1, 13, 57, 58, -1, 59, 60, 61, -1, 59, 61, 62, -1, 53, 52, 63, -1, 20, 51, 17, -1, 64, 17, 51, -1, 51, 50, 64, -1, 27, 64, 50, -1, 28, 27, 50, -1, 56, 62, 35, -1, 62, 47, 35, -1, 38, 41, 46, -1, 41, 35, 46, -1, 65, 66, 67, -1, 68, 69, 70, -1, 68, 70, 71, -1, 63, 52, 56, -1, 63, 56, 55, -1, 34, 33, 51, -1, 72, 58, 57, -1, 54, 53, 73, -1, 54, 73, 74, -1, 71, 70, 75, -1, 71, 75, 76, -1, 42, 50, 43, -1, 37, 77, 48, -1, 78, 68, 71, -1, 78, 71, 76, -1, 79, 72, 57, -1, 34, 51, 20, -1, 34, 20, 19, -1, 7, 10, 1, -1, 1, 80, 11, -1, 52, 54, 81, -1, 82, 81, 54, -1, 78, 83, 69, -1, 78, 69, 68, -1, 29, 28, 50, -1, 29, 50, 42, -1, 24, 37, 25, -1, 84, 74, 85, -1, 59, 85, 74, -1, 82, 86, 81, -1, 82, 54, 84, -1, 74, 84, 54, -1, 26, 25, 37, -1, 72, 4, 58, -1, 87, 4, 72, -1, 4, 6, 58, -1, 13, 58, 6, -1, 88, 0, 31, -1, 81, 86, 89, -1, 64, 49, 17, -1, 18, 17, 49, -1, 78, 56, 81, -1, 76, 62, 78, -1, 59, 62, 85, -1, 76, 85, 62, -1, 62, 56, 78, -1, 52, 81, 56, -1, 85, 90, 84, -1, 26, 36, 23, -1, 75, 70, 69, -1, 75, 69, 83, -1, 85, 91, 90, -1, 57, 22, 79, -1, 12, 14, 57, -1, 14, 22, 57, -1, 92, 79, 22, -1, 47, 46, 35, -1, 36, 35, 93, -1, 93, 35, 41, -1, 23, 36, 93, -1, 93, 94, 23, -1, 63, 89, 53, -1, 72, 79, 92, -1, 72, 92, 87, -1, 86, 82, 84, -1, 86, 84, 90, -1, 24, 95, 77, -1, 60, 73, 91, -1, 90, 91, 73, -1, 91, 85, 76, -1, 91, 76, 75, -1, 80, 31, 11, -1, 73, 53, 90, -1, 86, 90, 53, -1, 83, 78, 81, -1, 83, 81, 89, -1, 40, 48, 77, -1, 24, 77, 37, -1, 75, 61, 91, -1, 83, 55, 75, -1, 63, 55, 89, -1, 86, 53, 89, -1, 83, 89, 55, -1, 55, 61, 75, -1, 60, 91, 61, -1, 95, 94, 93, -1, 95, 93, 77, -1, 74, 73, 60, -1, 74, 60, 59, -1, 94, 95, 24, -1, 94, 24, 23, -1, 0, 88, 9, -1, 41, 40, 77, -1, 41, 77, 93, -1, 5, 21, 14, -1, 5, 14, 6, -1, 26, 37, 36, -1, 11, 31, 21, -1, 11, 21, 5, -1, 31, 80, 88, -1, 67, 61, 48, -1, 55, 48, 61, -1, 67, 48, 65, -1, 40, 65, 48, -1, 39, 65, 40, -1, 87, 92, 22, -1, 87, 22, 4, -1, 47, 67, 66, -1, 47, 66, 45, -1, 8, 7, 0, -1, 45, 66, 65, -1, 45, 65, 46, -1, 16, 15, 27, -1, 16, 27, 30, -1, 62, 61, 67, -1, 62, 67, 47, -1, 46, 65, 39, -1, 46, 39, 38, -1, 44, 43, 33, -1, 44, 33, 32, -1, 49, 10, 30, -1, 16, 30, 10, -1, 49, 80, 10, -1, 80, 1, 10, -1, 15, 9, 27, -1, 64, 27, 9, -1, 88, 64, 9, -1, 8, 0, 9, -1, 88, 80, 64, -1, 49, 64, 80, -1
            ]
          }
        }
      ]
      name "group_0_16777215"
    }
  ]
  name "caminho.obj"
}
DEF Lombada Solid {
  translation 0.77638 0.0025 -0.172243
  rotation -0.5921308755788088 0.5921118755828012 0.5466118851434629 2.14101
  children [
    DEF Lombada Shape {
      geometry Cylinder {
        height 0.5
        radius 0.0025
      }
    }
  ]
  name "solid(1)"
  boundingObject USE Lombada
}
