#VRML_SIM R2021a utf8
WorldInfo {
  coordinateSystem "NUE"
}
Viewpoint {
  orientation -0.07422255991468737 -0.9912144705365435 -0.10947549953606138 1.958183999635274
  position -2.4094614980959044 0.6804377373716302 -1.5383116169904327
}
TexturedBackground {
}
TexturedBackgroundLight {
}
RectangleArena {
  floorSize 2 2
  floorAppearance Appearance {
    material Material {
      ambientIntensity 0
      diffuseColor 1 1 1
      emissiveColor 1 1 1
      shininess 0
      specularColor 1 1 1
    }
    texture ImageTexture {
      url [
        "textures/circulo_large.jpg"
      ]
      repeatS FALSE
      repeatT FALSE
    }
    textureTransform TextureTransform {
      scale 0.25 0.25
    }
  }
}
Robot {
  translation 0.23704486232623154 0.029264917098718868 -0.773943101560241
  rotation 0.005642162269244377 0.9999831651818328 0.0013547537970775348 2.669775312177264
  children [
    DistanceSensor {
      translation 0.1 -0.005 0.07
      rotation 0 0 -1 1.5707996938995747
      children [
        DEF SensorInfravermelho Group {
          children [
            DEF Base Transform {
              children [
                Shape {
                  appearance PBRAppearance {
                    baseColor 0.1 0.1 0.1
                    roughness 1
                    metalness 0
                    IBLStrength 0
                  }
                  geometry Box {
                    size 0.005 0.012 0.0058
                  }
                }
              ]
            }
            DEF Receptor Transform {
              translation 0.002 -0.0025 0
              rotation 0 0 1 1.5708
              children [
                Shape {
                  appearance PBRAppearance {
                    baseColor 0.2 0.1 0.2
                  }
                  geometry Capsule {
                    height 0.005
                    radius 0.0015
                  }
                }
              ]
            }
            DEF Emissor Transform {
              translation 0.002 0.0025 0
              rotation 0 0 1 1.5708
              children [
                Shape {
                  appearance PBRAppearance {
                    baseColor 0.4 0.4 1
                  }
                  geometry Capsule {
                    height 0.005
                    radius 0.0015
                  }
                }
              ]
            }
          ]
        }
      ]
      name "l1"
      boundingObject USE SensorInfravermelho
      physics Physics {
      }
      type "infra-red"
    }
    DistanceSensor {
      translation 0.1 -0.005 0.035
      rotation 0 0 -1 1.5707996938995747
      children [
        DEF tcrt Shape {
          appearance PBRAppearance {
          }
          geometry Box {
            size 0.01 0.01 0.005
          }
        }
      ]
      name "l2"
      boundingObject USE tcrt
      physics Physics {
      }
      type "infra-red"
    }
    DistanceSensor {
      translation 0.1 -0.005 0
      rotation 0 0 -1 1.5707996938995747
      children [
        DEF tcrt Shape {
          appearance PBRAppearance {
          }
          geometry Box {
            size 0.01 0.01 0.005
          }
        }
      ]
      name "l3"
      boundingObject USE tcrt
      physics Physics {
      }
      type "infra-red"
    }
    DistanceSensor {
      translation 0.1 -0.005 -0.035
      rotation 0 0 -1 1.5707996938995747
      children [
        DEF tcrt Shape {
          appearance PBRAppearance {
          }
          geometry Box {
            size 0.01 0.01 0.005
          }
        }
      ]
      name "l4"
      boundingObject USE tcrt
      physics Physics {
      }
      type "infra-red"
    }
    DistanceSensor {
      translation 0.1 -0.005 -0.07
      rotation 0 0 -1 1.5707996938995747
      children [
        DEF tcrt Shape {
          appearance PBRAppearance {
          }
          geometry Box {
            size 0.01 0.01 0.005
          }
        }
      ]
      name "l5"
      boundingObject USE tcrt
      physics Physics {
      }
      type "infra-red"
    }
    DistanceSensor {
      translation 0.1085 0.015 0
      children [
        DEF SensorUltrassonico Group {
          children [
            DEF Base Transform {
              children [
                Shape {
                  appearance PBRAppearance {
                    baseColor 0.1 0.2 1
                  }
                  geometry Box {
                    size 0.0015 0.02 0.045
                  }
                }
              ]
            }
            DEF Cilindro_1 Transform {
              translation 0.005 0 0.013
              rotation 0 0 1 -1.5707996938995747
              children [
                Shape {
                  appearance PBRAppearance {
                    baseColor 0.454902 0.454902 0.678431
                    metalness 0.5
                    normalMapFactor 0.5
                    emissiveColor 0.1 0.1 0.1
                  }
                  geometry Cylinder {
                    height 0.012
                    radius 0.008
                  }
                }
              ]
              translationStep 0
            }
            DEF Cilindro_2 Transform {
              translation 0.005 0 -0.013
              rotation 0 0 1 -1.5707996938995747
              children [
                Shape {
                  appearance PBRAppearance {
                    baseColor 0.454902 0.454902 0.678431
                    metalness 0.5
                    normalMapFactor 0.5
                    emissiveColor 0.1 0.1 0.1
                  }
                  geometry Cylinder {
                    height 0.012
                    radius 0.008
                  }
                }
              ]
              translationStep 0
            }
          ]
        }
      ]
      name "d1"
      contactMaterial ""
      boundingObject USE SensorUltrassonico
      physics Physics {
      }
      recognitionColors [
        1 1 1
      ]
      type "sonar"
      numberOfRays 5
      aperture 1
      resolution 0.001
    }
    DEF RodaL HingeJoint {
      jointParameters HingeJointParameters {
        position 6.2765948375359
        axis 0 1 0
        anchor -0.1 0 0
      }
      endPoint Solid {
        translation -0.09999998165762318 1.6210927591894778e-06 1.2106887411541443e-10
        rotation 0 1 0 6.27659483753588
        children [
          DEF JuntaRoda HingeJoint {
            jointParameters HingeJointParameters {
              position -358.12023129978064
              axis 0 0 1
              anchor -0.02 -0.018 0
            }
            endPoint Solid {
              translation -0.02 -0.018 0
              rotation 0.39427222291246844 -0.6498266812019129 0.649826668149106 3.892712585465476
              children [
                DEF CalotaRodaL Transform {
                  children [
                    Shape {
                      appearance PBRAppearance {
                        baseColorMap ImageTexture {
                          url [
                            "textures/calota_preta.jpg"
                          ]
                        }
                        metalness 0
                      }
                      geometry Cylinder {
                        height 0.005
                        radius 0.009
                      }
                    }
                  ]
                }
                DEF rodaLroda Shape {
                  appearance PBRAppearance {
                    baseColor 0 0 0
                    metalness 0
                  }
                  geometry Cylinder {
                    height 0.0045
                    radius 0.01
                  }
                }
              ]
              boundingObject USE rodaLroda
              physics Physics {
              }
              linearVelocity 9.51869165239209e-10 1.0935286668247318e-08 1.0739926868137045e-09
              angularVelocity 7.541225495059621e-08 -7.213175589640253e-08 -1.1176863283578836e-07
            }
          }
          DEF rodaLEixoHorizontal Transform {
            translation -0.01 -0.018 0
            rotation 0 0 1 1.5708
            children [
              Shape {
                appearance PBRAppearance {
                  baseColor 0.580392 0.580392 0.580392
                  metalness 0
                }
                geometry Capsule {
                  height 0.02
                  radius 0.005
                  subdivision 24
                }
              }
            ]
          }
          DEF rodaLEixoVertical Transform {
            translation 0 -0.007 0
            children [
              Shape {
                appearance PBRAppearance {
                  baseColor 0.580392 0.580392 0.580392
                  metalness 0
                }
                geometry Capsule {
                  height 0.02
                  radius 0.005
                  subdivision 24
                }
              }
            ]
          }
        ]
        name "roda_boba"
        boundingObject Group {
          children [
            USE rodaLEixoHorizontal
            USE rodaLEixoVertical
          ]
        }
        physics Physics {
        }
        linearVelocity 1.8134784871888094e-09 1.8074608280353135e-09 4.076961351486968e-10
        angularVelocity 5.0953003964364623e-08 -7.212772299648947e-08 -6.460317397167127e-08
      }
    }
    DEF RodaE HingeJoint {
      jointParameters HingeJointParameters {
        position 97.61941420432326
        axis 0 0 -1
        anchor 0.05 0 -0.07
      }
      device [
        RotationalMotor {
          name "motorE"
        }
      ]
      endPoint Solid {
        translation 0.04999640281113854 -1.381044254060467e-06 -0.0699998308138625
        rotation 0.08488691463395714 0.704273725244112 0.7048352514273873 2.9720889715118006
        children [
          DEF Calota Transform {
            children [
              Shape {
                appearance PBRAppearance {
                  baseColor 1 1 0
                  baseColorMap ImageTexture {
                    url [
                      "textures/calota_preta.jpg"
                    ]
                  }
                  metalness 0
                }
                geometry Cylinder {
                  height 0.031
                  radius 0.029
                }
              }
            ]
          }
          DEF rodaE Shape {
            appearance PBRAppearance {
              baseColorMap ImageTexture {
                url [
                  "textures/caster_wheel_base_color.jpg"
                ]
              }
              metalness 0
            }
            geometry Cylinder {
              height 0.03
              radius 0.03
            }
          }
        ]
        name "roda_esquerda"
        boundingObject USE rodaE
        physics Physics {
        }
        linearVelocity 2.3927933728540154e-09 1.594176592920313e-08 1.5754831608820517e-09
        angularVelocity 5.183940684001008e-08 6.0475411948535775e-09 -6.43503915305015e-08
      }
    }
    DEF RodaD HingeJoint {
      jointParameters HingeJointParameters {
        position 80.02322992998393
        axis 0 0 -1
        anchor 0.05 0 0.07
      }
      device [
        RotationalMotor {
          name "motorD"
        }
      ]
      endPoint Solid {
        translation 0.050000971921648686 1.6942401658425965e-06 0.07000060852157688
        rotation -0.5349790836057924 -0.597172614467143 -0.5976472610451616 4.124729368161167
        children [
          DEF Calota Transform {
            children [
              Shape {
                appearance PBRAppearance {
                  baseColor 1 1 0
                  baseColorMap ImageTexture {
                    url [
                      "textures/calota_preta.jpg"
                    ]
                  }
                  metalness 0
                }
                geometry Cylinder {
                  height 0.031
                  radius 0.029
                }
              }
            ]
          }
          DEF rodaD Shape {
            appearance PBRAppearance {
              baseColorMap ImageTexture {
                url [
                  "textures/caster_wheel.jpg"
                ]
              }
              metalness 0
            }
            geometry Cylinder {
              height 0.03
              radius 0.03
            }
          }
        ]
        name "roda_direita"
        boundingObject USE rodaD
        physics Physics {
        }
        linearVelocity 1.6345210396808974e-09 1.798066719346264e-08 1.2146185139429147e-09
        angularVelocity 5.182670901550391e-08 6.047414746270385e-09 -6.43677483768277e-08
      }
    }
    DEF Estrutura Transform {
      children [
        Shape {
          appearance PBRAppearance {
            baseColor 0.666667 0.666667 0
            baseColorMap ImageTexture {
              url [
                "textures/desktop_wood.jpg"
              ]
            }
            metalness 0
          }
          geometry Box {
            size 0.22 0.01 0.16
          }
        }
      ]
    }
  ]
  name "Robo_Ifes"
  boundingObject USE Estrutura
  physics Physics {
  }
  controller "controlador-principal"
}
